2024-02-28 09:55:55,843 INFO    MainThread:1128353 [wandb_setup.py:_flush():76] Current SDK version is 0.16.3
2024-02-28 09:55:55,843 INFO    MainThread:1128353 [wandb_setup.py:_flush():76] Configure stats pid to 1128353
2024-02-28 09:55:55,843 INFO    MainThread:1128353 [wandb_setup.py:_flush():76] Loading settings from /home/amax/.config/wandb/settings
2024-02-28 09:55:55,843 INFO    MainThread:1128353 [wandb_setup.py:_flush():76] Loading settings from /nvme/zecheng/state-space-model/mamba-trainer/wandb/settings
2024-02-28 09:55:55,843 INFO    MainThread:1128353 [wandb_setup.py:_flush():76] Loading settings from environment variables: {}
2024-02-28 09:55:55,843 INFO    MainThread:1128353 [wandb_setup.py:_flush():76] Applying setup settings: {'_disable_service': False}
2024-02-28 09:55:55,843 INFO    MainThread:1128353 [wandb_setup.py:_flush():76] Inferring run settings from compute environment: {'program_relpath': 'train_mamba.py', 'program_abspath': '/nvme/zecheng/state-space-model/mamba-trainer/train_mamba.py', 'program': '/nvme/zecheng/state-space-model/mamba-trainer/train_mamba.py'}
2024-02-28 09:55:55,843 INFO    MainThread:1128353 [wandb_init.py:_log_setup():526] Logging user logs to /nvme/zecheng/state-space-model/mamba-trainer/wandb/run-20240228_095555-yaqanu10/logs/debug.log
2024-02-28 09:55:55,843 INFO    MainThread:1128353 [wandb_init.py:_log_setup():527] Logging internal logs to /nvme/zecheng/state-space-model/mamba-trainer/wandb/run-20240228_095555-yaqanu10/logs/debug-internal.log
2024-02-28 09:55:55,843 INFO    MainThread:1128353 [wandb_init.py:init():566] calling init triggers
2024-02-28 09:55:55,843 INFO    MainThread:1128353 [wandb_init.py:init():573] wandb.init called with sweep_config: {}
config: {}
2024-02-28 09:55:55,843 INFO    MainThread:1128353 [wandb_init.py:init():616] starting backend
2024-02-28 09:55:55,843 INFO    MainThread:1128353 [wandb_init.py:init():620] setting up manager
2024-02-28 09:55:55,844 INFO    MainThread:1128353 [backend.py:_multiprocessing_setup():105] multiprocessing start_methods=fork,spawn,forkserver, using: spawn
2024-02-28 09:55:55,846 INFO    MainThread:1128353 [wandb_init.py:init():628] backend started and connected
2024-02-28 09:55:55,847 INFO    MainThread:1128353 [wandb_init.py:init():720] updated telemetry
2024-02-28 09:55:55,853 INFO    MainThread:1128353 [wandb_init.py:init():753] communicating run to backend with 90.0 second timeout
2024-02-28 09:57:02,878 INFO    Thread-2 (wrapped_target):1128353 [retry.py:__call__():172] Retry attempt failed:
Traceback (most recent call last):
  File "/home/amax/anaconda3/envs/zecheng/lib/python3.10/site-packages/urllib3/connection.py", line 203, in _new_conn
    sock = connection.create_connection(
  File "/home/amax/anaconda3/envs/zecheng/lib/python3.10/site-packages/urllib3/util/connection.py", line 85, in create_connection
    raise err
  File "/home/amax/anaconda3/envs/zecheng/lib/python3.10/site-packages/urllib3/util/connection.py", line 73, in create_connection
    sock.connect(sa)
TimeoutError: timed out

The above exception was the direct cause of the following exception:

Traceback (most recent call last):
  File "/home/amax/anaconda3/envs/zecheng/lib/python3.10/site-packages/urllib3/connectionpool.py", line 790, in urlopen
    response = self._make_request(
  File "/home/amax/anaconda3/envs/zecheng/lib/python3.10/site-packages/urllib3/connectionpool.py", line 491, in _make_request
    raise new_e
  File "/home/amax/anaconda3/envs/zecheng/lib/python3.10/site-packages/urllib3/connectionpool.py", line 467, in _make_request
    self._validate_conn(conn)
  File "/home/amax/anaconda3/envs/zecheng/lib/python3.10/site-packages/urllib3/connectionpool.py", line 1096, in _validate_conn
    conn.connect()
  File "/home/amax/anaconda3/envs/zecheng/lib/python3.10/site-packages/urllib3/connection.py", line 611, in connect
    self.sock = sock = self._new_conn()
  File "/home/amax/anaconda3/envs/zecheng/lib/python3.10/site-packages/urllib3/connection.py", line 212, in _new_conn
    raise ConnectTimeoutError(
urllib3.exceptions.ConnectTimeoutError: (<urllib3.connection.HTTPSConnection object at 0x7f5f6f759960>, 'Connection to api.wandb.ai timed out. (connect timeout=20)')

The above exception was the direct cause of the following exception:

Traceback (most recent call last):
  File "/home/amax/anaconda3/envs/zecheng/lib/python3.10/site-packages/requests/adapters.py", line 486, in send
    resp = conn.urlopen(
  File "/home/amax/anaconda3/envs/zecheng/lib/python3.10/site-packages/urllib3/connectionpool.py", line 844, in urlopen
    retries = retries.increment(
  File "/home/amax/anaconda3/envs/zecheng/lib/python3.10/site-packages/urllib3/util/retry.py", line 515, in increment
    raise MaxRetryError(_pool, url, reason) from reason  # type: ignore[arg-type]
urllib3.exceptions.MaxRetryError: HTTPSConnectionPool(host='api.wandb.ai', port=443): Max retries exceeded with url: /graphql (Caused by ConnectTimeoutError(<urllib3.connection.HTTPSConnection object at 0x7f5f6f759960>, 'Connection to api.wandb.ai timed out. (connect timeout=20)'))

During handling of the above exception, another exception occurred:

Traceback (most recent call last):
  File "/home/amax/anaconda3/envs/zecheng/lib/python3.10/site-packages/wandb/sdk/lib/retry.py", line 131, in __call__
    result = self._call_fn(*args, **kwargs)
  File "/home/amax/anaconda3/envs/zecheng/lib/python3.10/site-packages/wandb/sdk/internal/internal_api.py", line 369, in execute
    return self.client.execute(*args, **kwargs)  # type: ignore
  File "/home/amax/anaconda3/envs/zecheng/lib/python3.10/site-packages/wandb/vendor/gql-0.2.0/wandb_gql/client.py", line 52, in execute
    result = self._get_result(document, *args, **kwargs)
  File "/home/amax/anaconda3/envs/zecheng/lib/python3.10/site-packages/wandb/vendor/gql-0.2.0/wandb_gql/client.py", line 60, in _get_result
    return self.transport.execute(document, *args, **kwargs)
  File "/home/amax/anaconda3/envs/zecheng/lib/python3.10/site-packages/wandb/sdk/lib/gql_request.py", line 58, in execute
    request = self.session.post(self.url, **post_args)
  File "/home/amax/anaconda3/envs/zecheng/lib/python3.10/site-packages/requests/sessions.py", line 637, in post
    return self.request("POST", url, data=data, json=json, **kwargs)
  File "/home/amax/anaconda3/envs/zecheng/lib/python3.10/site-packages/requests/sessions.py", line 589, in request
    resp = self.send(prep, **send_kwargs)
  File "/home/amax/anaconda3/envs/zecheng/lib/python3.10/site-packages/requests/sessions.py", line 703, in send
    r = adapter.send(request, **kwargs)
  File "/home/amax/anaconda3/envs/zecheng/lib/python3.10/site-packages/requests/adapters.py", line 507, in send
    raise ConnectTimeout(e, request=request)
requests.exceptions.ConnectTimeout: HTTPSConnectionPool(host='api.wandb.ai', port=443): Max retries exceeded with url: /graphql (Caused by ConnectTimeoutError(<urllib3.connection.HTTPSConnection object at 0x7f5f6f759960>, 'Connection to api.wandb.ai timed out. (connect timeout=20)'))
2024-02-28 09:57:19,848 WARNING MainThread:1128353 [wandb_init.py:init():1198] interrupted
Traceback (most recent call last):
  File "/home/amax/anaconda3/envs/zecheng/lib/python3.10/site-packages/wandb/sdk/wandb_init.py", line 1176, in init
    run = wi.init()
  File "/home/amax/anaconda3/envs/zecheng/lib/python3.10/site-packages/wandb/sdk/wandb_init.py", line 756, in init
    result = run_init_handle.wait(
  File "/home/amax/anaconda3/envs/zecheng/lib/python3.10/site-packages/wandb/sdk/lib/mailbox.py", line 283, in wait
    found, abandoned = self._slot._get_and_clear(timeout=wait_timeout)
  File "/home/amax/anaconda3/envs/zecheng/lib/python3.10/site-packages/wandb/sdk/lib/mailbox.py", line 130, in _get_and_clear
    if self._wait(timeout=timeout):
  File "/home/amax/anaconda3/envs/zecheng/lib/python3.10/site-packages/wandb/sdk/lib/mailbox.py", line 126, in _wait
    return self._event.wait(timeout=timeout)
  File "/home/amax/anaconda3/envs/zecheng/lib/python3.10/threading.py", line 600, in wait
    signaled = self._cond.wait(timeout)
  File "/home/amax/anaconda3/envs/zecheng/lib/python3.10/threading.py", line 324, in wait
    gotit = waiter.acquire(True, timeout)
KeyboardInterrupt
